<?xml version="1.0"?>
<robot name="robot">

<material name="blue">
    <color rgba="0 0 0.8 1"/>
  </material>
  <material name="black">
    <color rgba="0 0 0 1"/>
  </material>
  <material name="white">
    <color rgba="1 1 1 1"/>
  </material>



<link name="base">

<inertial>
   <origin rpy="0 0 0" xyz="0 0 0.0"/>
   <mass value="10"/>
  
   <inertia ixx="00.154" ixy="0" ixz="0" iyy="0.30" iyz="0"  izz="00.054"/>
</inertial>


<collision>
      <geometry>
       <mesh filename="package://diff_drive_robot/dae/frame.dae" scale = "0.001 0.001 0.001"/>
      </geometry>
        <origin rpy="1.57 0 0" xyz="-0.2 0.3 0"/>
    </collision>

<visual>
      <geometry>
       <mesh filename="package://diff_drive_robot/dae/frame.dae" scale = "0.001 0.001 0.001"/>
      </geometry>
        <origin rpy="1.57 0 0" xyz="-0.2 0.3 0"/>
      <material name="blue"/>
    </visual>

</link>






<link name="wheel_r">
<inertial>
   <origin rpy="1.57 0 0" xyz="0.2 0 0"/>
   <mass value="0.01"/>
   <inertia ixx="0.0160" ixy="0" ixz="0" iyy="0.0160" iyz="0"  izz="0.0144"/>
</inertial>
<collision>
      <geometry>
         <mesh filename="package://diff_drive_robot/dae/wheel.dae" scale = "0.001 0.001 0.001"/>
      </geometry>
        <origin rpy="0 0 3.14" xyz="0.2 0.065 -0.065"/>
    </collision>


    <visual>
      <geometry>
         <mesh filename="package://diff_drive_robot/dae/wheel.dae" scale = "0.001 0.001 0.001"/>
      </geometry>
        <origin rpy="0 0 3.14" xyz="0.2 0.065 -0.065"/>
      <material name="blue"/>
    </visual>
  </link>

  <joint name="right_j" type="continuous">
    <parent link="base"/>
    <child link="wheel_r"/>
    <origin xyz="0 0 0.0198"/>
    
    
    <axis  xyz = "1 0 0"/>
  </joint>

<gazebo reference="wheel_r">
    <mu1>0.8</mu1>
    <mu2>0.8</mu2>
    
  </gazebo>


<link name="wheel_l">
<inertial>
   <origin rpy="1.57 0 0" xyz="0.2 0 0"/>
   <mass value="0.01"/>
   <inertia ixx="0.0160" ixy="0" ixz="0" iyy="0.0160" iyz="0"  izz="0.0144"/>
</inertial>
<collision>
      <geometry>
         <mesh filename="package://diff_drive_robot/dae/wheel.dae" scale = "0.001 0.001 0.001"/>
      </geometry>
        <origin rpy="0 0 0" xyz="-0.2 -0.065 -0.065"/>
    </collision>


    <visual>
      <geometry>
         <mesh filename="package://diff_drive_robot/dae/wheel.dae" scale = "0.001 0.001 0.001"/>
      </geometry>
        <origin rpy="0 0 0" xyz="-0.2 -0.065 -0.065"/>
      <material name="blue"/>
    </visual>
  </link>

  <joint name="left_j" type="continuous">
    <parent link="base"/>
    <child link="wheel_l"/>
    <origin xyz="0 0 0.0198"/>
    
    
    <axis  xyz = "1 0 0"/>
  </joint>


<gazebo reference="wheel_l">
    <mu1>0.8</mu1>
    <mu2>0.8</mu2>
    
  </gazebo>






<link name="caster_fr">
<inertial>
   <origin rpy="1.57 0 0" xyz="0.2 0 0"/>
   <mass value="0.01"/>
   <inertia ixx="0.0160" ixy="0" ixz="0" iyy="0.0160" iyz="0"  izz="0.0144"/>
</inertial>
<collision>
      <geometry>
         <mesh filename="package://diff_drive_robot/dae/caster_joint.dae" scale = "0.001 0.001 0.001"/>
      </geometry>
        <origin rpy="1.57 0 3.14" xyz="0.02 -0.055 -0.020"/>
    </collision>


!--changing Z value to set the wheel--!
    <visual>
      <geometry>
         <mesh filename="package://diff_drive_robot/dae/caster_joint.dae" scale = "0.001 0.001 0.001"/>
      </geometry>
        <origin rpy="1.57 0 3.14" xyz="0.02 -0.055 -0.020"/>
      <material name="blue"/>
    </visual>
  </link>


  <joint name="caster_fr_joint" type="fixed">
    <parent link="base"/>
    <child link="caster_fr"/>
    <origin xyz="0.150 0.25 0"/>
    
    
    <axis  xyz = "0 0 1"/>
  </joint>









<link name="caster_wheel_fr_out">
<inertial>
   <origin rpy="1.57 0 0" xyz="0.2 0 0"/>
   <mass value="0.01"/>
   <inertia ixx="5.1458e-5" iyy="5.1458e-5" izz="6.125e-5"
           ixy="0" ixz="0" iyz="0"/>
</inertial>
<collision>
      <geometry>
         <mesh filename="package://diff_drive_robot/dae/caster.dae" scale = "0.001 0.001 0.001"/>
      </geometry>
        <origin rpy="1.57 0 0" xyz="0 0.030 -0.03"/>
    </collision>


!--changing Z value to set the wheel--!
    <visual>
      <geometry>
         <mesh filename="package://diff_drive_robot/dae/caster.dae" scale = "0.001 0.001 0.001"/>
      </geometry>
        <origin rpy="1.57 0 0" xyz="0 0.030 -0.03"/>
      <material name="blue"/>
    </visual>
  </link>


  <joint name="caster_fr_wheel_out_joint" type="continuous">
    <parent link="caster_fr"/>
    <child link="caster_wheel_fr_out"/>
    <origin xyz="0 -0.0235 -0.015"/>
    
    
    <axis  xyz = "1 0 0"/>
  </joint>



<gazebo reference="caster_wheel_fr_out">
    <mu1>0.0</mu1>
    <mu2>0.0</mu2>
    
  </gazebo>


<link name="caster_wheel_fr_in">
<inertial>
   <origin rpy="1.57 0 0" xyz="0.2 0 0"/>
   <mass value="0.01"/>
   <inertia ixx="5.1458e-5" iyy="5.1458e-5" izz="6.125e-5"
           ixy="0" ixz="0" iyz="0"/>
</inertial>
<collision>
      <geometry>
         <mesh filename="package://diff_drive_robot/dae/caster.dae" scale = "0.001 0.001 0.001"/>
      </geometry>
        <origin rpy="1.57 0 3.14" xyz="0 -0.030 -0.03"/>
    </collision>


!--changing Z value to set the wheel--!
    <visual>
      <geometry>
         <mesh filename="package://diff_drive_robot/dae/caster.dae" scale = "0.001 0.001 0.001"/>
      </geometry>
        <origin rpy="1.57 0 3.14" xyz="0 -0.030 -0.03"/>
      <material name="blue"/>
    </visual>
  </link>


  <joint name="caster_fr_wheel_in_joint" type="continuous">
    <parent link="caster_fr"/>
    <child link="caster_wheel_fr_in"/>
    <origin xyz="0 -0.0235 -0.015"/>
    
    
    <axis  xyz = "1 0 0"/>
  </joint>


<gazebo reference="caster_wheel_fr_in">
    <mu1>0.0</mu1>
    <mu2>0.0</mu2>
    
  </gazebo>















<link name="caster_fl">
<inertial>
   <origin rpy="1.57 0 0" xyz="0.2 0 0"/>
   <mass value="0.01"/>
   <inertia ixx="0.0160" ixy="0" ixz="0" iyy="0.0160" iyz="0"  izz="0.0144"/>
</inertial>
<collision>
      <geometry>
         <mesh filename="package://diff_drive_robot/dae/caster_joint.dae" scale = "0.001 0.001 0.001"/>
      </geometry>
        <origin rpy="1.57 0 3.14" xyz="0.02 -0.055 -0.020"/>
    </collision>


!--changing Z value to set the wheel--!
    <visual>
      <geometry>
         <mesh filename="package://diff_drive_robot/dae/caster_joint.dae" scale = "0.001 0.001 0.001"/>
      </geometry>
        <origin rpy="1.57 0 3.14" xyz="0.02 -0.055 -0.020"/>
      <material name="blue"/>
    </visual>
  </link>


  <joint name="caster_fl_joint" type="fixed">
    <parent link="base"/>
    <child link="caster_fl"/>
    <origin xyz="-0.150 0.25 0"/>
    
    
    <axis  xyz = "0 0 1"/>
  </joint>












<link name="caster_wheel_fl_out">
<inertial>
   <origin rpy="1.57 0 0" xyz="0.2 0 0"/>
   <mass value="0.01"/>
   <inertia ixx="5.1458e-5" iyy="5.1458e-5" izz="6.125e-5"
           ixy="0" ixz="0" iyz="0"/>
</inertial>
<collision>
      <geometry>
         <mesh filename="package://diff_drive_robot/dae/caster.dae" scale = "0.001 0.001 0.001"/>
      </geometry>
        <origin rpy="1.57 0 3.14" xyz="0 -0.030 -0.03"/>
    </collision>


!--changing Z value to set the wheel--!
    <visual>
      <geometry>
         <mesh filename="package://diff_drive_robot/dae/caster.dae" scale = "0.001 0.001 0.001"/>
      </geometry>
        <origin rpy="1.57 0 3.14" xyz="0 -0.030 -0.03"/>
      <material name="blue"/>
    </visual>
  </link>


  <joint name="caster_fl_wheel_out_joint" type="continuous">
    <parent link="caster_fl"/>
    <child link="caster_wheel_fl_out"/>
    <origin xyz="0 -0.0235 -0.015"/>
    
    
    <axis  xyz = "1 0 0"/>
  </joint>


<gazebo reference="caster_wheel_fl_out">
    <mu1>0.0</mu1>
    <mu2>0.0</mu2>
    
  </gazebo>



<link name="caster_wheel_fl_in">
<inertial>
   <origin rpy="1.57 0 0" xyz="0.2 0 0"/>
   <mass value="0.01"/>
   <inertia ixx="5.1458e-5" iyy="5.1458e-5" izz="6.125e-5"
           ixy="0" ixz="0" iyz="0"/>
</inertial>
<collision>
      <geometry>
         <mesh filename="package://diff_drive_robot/dae/caster.dae" scale = "0.001 0.001 0.001"/>
      </geometry>
        <origin rpy="1.57 0 0" xyz="0 0.030 -0.03"/>
    </collision>


!--changing Z value to set the wheel--!
    <visual>
      <geometry>
         <mesh filename="package://diff_drive_robot/dae/caster.dae" scale = "0.001 0.001 0.001"/>
      </geometry>
        <origin rpy="1.57 0 0" xyz="0 0.030 -0.03"/>
      <material name="blue"/>
    </visual>
  </link>


  <joint name="caster_fl_wheel_in_joint" type="continuous">
    <parent link="caster_fl"/>
    <child link="caster_wheel_fl_in"/>
    <origin xyz="0 -0.0235 -0.015"/>
    
    
    <axis  xyz = "1 0 0"/>
  </joint>





<gazebo reference="caster_wheel_fl_in">
    <mu1>0.0</mu1>
    <mu2>0.0</mu2>
    
  </gazebo>









<link name="caster_br">
<inertial>
   <origin rpy="1.57 0 0" xyz="0.2 0 0"/>
   <mass value="0.01"/>
   <inertia ixx="0.0160" ixy="0" ixz="0" iyy="0.0160" iyz="0"  izz="0.0144"/>
</inertial>
<collision>
      <geometry>
         <mesh filename="package://diff_drive_robot/dae/caster_joint.dae" scale = "0.001 0.001 0.001"/>
      </geometry>
        <origin rpy="1.57 0 3.14" xyz="0.02 -0.055 -0.020"/>
    </collision>


!--changing Z value to set the wheel--!
    <visual>
      <geometry>
         <mesh filename="package://diff_drive_robot/dae/caster_joint.dae" scale = "0.001 0.001 0.001"/>
      </geometry>
        <origin rpy="1.57 0 3.14" xyz="0.02 -0.055 -0.020"/>
      <material name="blue"/>
    </visual>
  </link>


  <joint name="caster_br_joint" type="fixed">
    <parent link="base"/>
    <child link="caster_br"/>
    <origin xyz="0.150 -0.25 0"/>
    
    
    <axis  xyz = "0 0 1"/>
  </joint>




<link name="caster_wheel_br_out">
<inertial>
   <origin rpy="1.57 0 0" xyz="0.2 0 0"/>
   <mass value="0.01"/>
   <inertia ixx="5.1458e-5" iyy="5.1458e-5" izz="6.125e-5"
           ixy="0" ixz="0" iyz="0"/>
</inertial>
<collision>
      <geometry>
         <mesh filename="package://diff_drive_robot/dae/caster.dae" scale = "0.001 0.001 0.001"/>
      </geometry>
        <origin rpy="1.57 0 0" xyz="0 0.030 -0.03"/>
    </collision>


!--changing Z value to set the wheel--!
    <visual>
      <geometry>
         <mesh filename="package://diff_drive_robot/dae/caster.dae" scale = "0.001 0.001 0.001"/>
      </geometry>
        <origin rpy="1.57 0 0" xyz="0 0.030 -0.03"/>
      <material name="blue"/>
    </visual>
  </link>


  <joint name="caster_br_wheel_out_joint" type="continuous">
    <parent link="caster_br"/>
    <child link="caster_wheel_br_out"/>
    <origin xyz="0 -0.0235 -0.015"/>
    
    
    <axis  xyz = "1 0 0"/>
  </joint>


<gazebo reference="caster_wheel_br_out">
    <mu1>0.0</mu1>
    <mu2>0.0</mu2>
    
  </gazebo>

<link name="caster_wheel_br_in">
<inertial>
   <origin rpy="1.57 0 0" xyz="0.2 0 0"/>
   <mass value="0.01"/>
   <inertia ixx="5.1458e-5" iyy="5.1458e-5" izz="6.125e-5"
           ixy="0" ixz="0" iyz="0"/>
</inertial>
<collision>
      <geometry>
         <mesh filename="package://diff_drive_robot/dae/caster.dae" scale = "0.001 0.001 0.001"/>
      </geometry>
        <origin rpy="1.57 0 3.14" xyz="0 -0.030 -0.03"/>
    </collision>


!--changing Z value to set the wheel--!
    <visual>
      <geometry>
         <mesh filename="package://diff_drive_robot/dae/caster.dae" scale = "0.001 0.001 0.001"/>
      </geometry>
        <origin rpy="1.57 0 3.14" xyz="0 -0.030 -0.03"/>
      <material name="blue"/>
    </visual>
  </link>


  <joint name="caster_br_wheel_in_joint" type="continuous">
    <parent link="caster_br"/>
    <child link="caster_wheel_br_in"/>
    <origin xyz="0 -0.0235 -0.015"/>
    
    
    <axis  xyz = "1 0 0"/>
  </joint>


<gazebo reference="caster_wheel_br_in">
    <mu1>0.0</mu1>
    <mu2>0.0</mu2>
    
  </gazebo>






<link name="caster_bl">
<inertial>
   <origin rpy="1.57 0 0" xyz="0.2 0 0"/>
   <mass value="0.01"/>
   <inertia ixx="0.0160" ixy="0" ixz="0" iyy="0.0160" iyz="0"  izz="0.0144"/>
</inertial>
<collision>
      <geometry>
         <mesh filename="package://diff_drive_robot/dae/caster_joint.dae" scale = "0.001 0.001 0.001"/>
      </geometry>
        <origin rpy="1.57 0 3.14" xyz="0.02 -0.055 -0.020"/>
    </collision>


!--changing Z value to set the wheel--!
    <visual>
      <geometry>
         <mesh filename="package://diff_drive_robot/dae/caster_joint.dae" scale = "0.001 0.001 0.001"/>
      </geometry>
        <origin rpy="1.57 0 3.14" xyz="0.02 -0.055 -0.020"/>
      <material name="blue"/>
    </visual>
  </link>


  <joint name="caster_bl_joint" type="fixed">
    <parent link="base"/>
    <child link="caster_bl"/>
    <origin xyz="-0.150 -0.25 0"/>
    
    
    <axis  xyz = "0 0 1"/>
  </joint>






<link name="caster_wheel_bl_out">
<inertial>
   <origin rpy="1.57 0 0" xyz="0.2 0 0"/>
   <mass value="0.01"/>
   <inertia ixx="5.1458e-5" iyy="5.1458e-5" izz="6.125e-5"
           ixy="0" ixz="0" iyz="0"/>
</inertial>
<collision>
      <geometry>
         <mesh filename="package://diff_drive_robot/dae/caster.dae" scale = "0.001 0.001 0.001"/>
      </geometry>
        <origin rpy="1.57 0 3.14" xyz="0 -0.030 -0.03"/>
    </collision>


!--changing Z value to set the wheel--!
    <visual>
      <geometry>
         <mesh filename="package://diff_drive_robot/dae/caster.dae" scale = "0.001 0.001 0.001"/>
      </geometry>
        <origin rpy="1.57 0 3.14" xyz="0 -0.030 -0.03"/>
      <material name="blue"/>
    </visual>
  </link>


  <joint name="caster_bl_wheel_out_joint" type="continuous">
    <parent link="caster_bl"/>
    <child link="caster_wheel_bl_out"/>
    <origin xyz="0 -0.0235 -0.015"/>
    
    
    <axis  xyz = "1 0 0"/>
  </joint>


<gazebo reference="caster_wheel_bl_out">
    <mu1>0.0</mu1>
    <mu2>0.0</mu2>
    
  </gazebo>

<link name="caster_wheel_bl_in">
<inertial>
   <origin rpy="1.57 0 0" xyz="0.2 0 0"/>
   <mass value="0.01"/>
   <inertia ixx="5.1458e-5" iyy="5.1458e-5" izz="6.125e-5"
           ixy="0" ixz="0" iyz="0"/>
</inertial>
<collision>
      <geometry>
         <mesh filename="package://diff_drive_robot/dae/caster.dae" scale = "0.001 0.001 0.001"/>
      </geometry>
        <origin rpy="1.57 0 0" xyz="0 0.030 -0.03"/>
    </collision>


!--changing Z value to set the wheel--!
    <visual>
      <geometry>
         <mesh filename="package://diff_drive_robot/dae/caster.dae" scale = "0.001 0.001 0.001"/>
      </geometry>
        <origin rpy="1.57 0 0" xyz="0 0.030 -0.03"/>
      <material name="blue"/>
    </visual>
  </link>


  <joint name="caster_bl_wheel_in_joint" type="continuous">
    <parent link="caster_bl"/>
    <child link="caster_wheel_bl_in"/>
    <origin xyz="0 -0.0235 -0.015"/>
    
    
    <axis  xyz = "1 0 0"/>
  </joint>


<gazebo reference="caster_wheel_bl_in">
    <mu1>0.0</mu1>
    <mu2>0.0</mu2>
    
  </gazebo>


<gazebo>
  <plugin name="differential_drive_controller" filename="libgazebo_ros_diff_drive.so">
    <alwaysOn>true</alwaysOn>
    <legacyMode>false</legacyMode>
    <updateRate>40</updateRate>
    <leftJoint>left_j</leftJoint>
    <rightJoint>right_j</rightJoint>
    <wheelSeparation>0.4</wheelSeparation>
    <wheelDiameter>0.137</wheelDiameter>
    <torque>50</torque>
    <commandTopic>/cmd_vel</commandTopic>
    <odometryTopic>odom</odometryTopic>
    <odometryFrame>odom</odometryFrame>
    <robotBaseFrame>base_footprint</robotBaseFrame>
  </plugin>
</gazebo>

</robot>
